Workbook

Sheet Title
A1: <<INDEX
D2: Project Name | E2: ClotQuant 2
D3: Document Details | E3: ClotQuant 2 Bringup Test
D4: Version | E4: 2
B6: Revision History
B7: Sr No | C7: Date | D7: Revision | E7: Release Notes | F7: Author
B8: 1 | C8: 45721 | D8: 1 | E8: Draft Version | F8: SqM Technologies
B9: 2 | C9: 45786 | D9: 2 | E9: Draft Version | F9: SqM Technologies
A18: <<INDEX

Sheet ClotQuant2-BD
B2: =_xlfn.DISPIMG("ID_996526CFEDAF4D1C933510E39AFAE41B",1) -> =DISPIMG("ID_996526CFEDAF4D1C933510E39AFAE41B",1) | Q2: Connector Mapping

Sheet Connection
B2: Connector Details - 1 | P2: Connector Details - 1

Sheet Index
A1: <<Title
B2: ClotQuant2 Board Bring up (CQ2BB) Report
B4: SR. No. | C4: Test Group | D4: Test Cases | E4: Status
B5: 1 | C5: NA | D5: Test Setup | E5: NA
B6: 2 | C6: NA | D6: Design History | E6: NA
B7: 3 | C7: CQ2BB1 | D7: Visual Inspection | E7: ='Visual Inspection'!C49 -> PASS
B8: 4 | C8: CQ2BB2 | D8: Impedance Measurement | E8: ='Impedance Measurement'!C31 -> PASS
B9: 5 | C9: CQ2BB3 | D9: Supply Rails | E9: ='Supply Rails'!F122 -> PASS
B10: 6 | C10: CQ2BB4 | D10: SWD LED code flash | E10: ='SWD LED CODE FLASH'!E18 -> PASS
B11: 7 | C11: CQ2BB5 | D11: Temperature Sensor | E11: ='Temprature Sensor'!E18 -> PASS
B12: 8 | C12: CQ2BB6 | D12: Display Test | E12: ='Display Test'!E19 -> PASS
B13: 9 | C13: CQ2BB7 | D13: Pipette | E13: =Pipette!E18 -> PASS
B14: 10 | C14: CQ2BB8 | D14: WiFi module | E14: ='Wifi module '!E19 -> PASS
B15: 11 | C15: CQ2BB9 | D15: BLE | E15: =BLE!E19 -> PASS
B16: 12 | C16: CQ2BB10 | D16: USB OTG 1 | E16: ='USB OTG1 Test'!D19 -> PASS
B17: 13 | C17: CQ2BB11 | D17: USB OTG 2 | E17: ='USB OTG2 Test'!D19 -> PASS
B18: 14 | C18: CQ2BB12 | D18: RFID | E18: =RFID!E19 -> PASS
B19: 15 | C19: CQ2BB13 | D19: Printer | E19: =Printer!E18 -> PASS
B20: 16 | C20: CQ2BB14 | D20: Ethernet | E20: =Ethernet!D20 -> PASS
B21: 17 | C21: CQ2BB15 | D21: Heater | E21: ='Heater '!E18 -> PASS
B22: 18 | C22: CQ2BB16 | D22: SDRAM | E22: =SDRAM!E18 -> PASS
B23: 19 | C23: CQ2BB17 | D23: QSPI NOR | E23: ='QSPI Flash'!E18 -> PASS
B24: 21 | C24: CQ2BB18 | D24: ADC Read | E24: =ADC!E18 -> PASS
B25: 22 | C25: CQ2BB19 | D25: IR LED test | E25: ='IR LED test '!E18 -> PASS
B26: 23 | C26: CQ2BB20 | D26: RS232 | E26: =RS232!E18 -> PASS
B27: 24 | C27: CQ2BB21 | D27: Buzzer | E27: =BUZZER!E18 -> PASS
B28: 25 | C28: CQ2BB22 | D28: FAN | E28: =FAN!E18 -> PASS
B29: 26 | C29: CQ2BB23 | D29: RTC | E29: =RTC!E18 -> PASS
B30: 27 | C30: CQ2BB24 | D30: Encryption IC | E30: ='Encryption IC'!E18 -> UNATTEMPTED
B31: 28 | C31: CQ2BB25 | D31: J11 Connector | E31: ='J11'!E18 -> UNATTEMPTED
A33: <<Title

Sheet Test Setup
A1: <<INDEX
B3: Board and Test Details
B4: Board Serial Number | C4: Version3.0 No.2
B5: Test Engineers | C5: Harshit Shakya
B6: Bare Board Received Date
B7: Assembled Board Received Date
B8: Date Of Testing
B10: List of Equipment
B11: Description | C11: Quantity | D11: Remark
B12: Power Supply | C12: 1
B13: DMM | C13: 1
B14: Oscilloscope | C14: 1
A18: <<INDEX

Sheet Design History
A1: <<INDEX
B2: Design History
B4: List Of DNI Components
B5: Reference Designator
B6: L6
B7: R27, R33, R64, R68, R81, R105
B8: U26 (Due to internal Vref of ADC)
B12: List Of HW Changes
B13: Reference Designator | C13: Date | D13: Change Description | E13: Images | F13: Remark
B14: U18 | C14: 45761 | D14: Connect U18 Pin33 (IRQN) to MCU PB1 pin. | E14: =_xlfn.DISPIMG("ID_3D7D83ABAF524CD7902A430F61513E27",1) -> =DISPIMG("ID_3D7D83ABAF524CD7902A430F61513E27",1) | F14: Changes has been done.
B15: J7 | C15: 45761 | D15: Printer Power J7 pin 3 requires a 5V supply. | E15: =_xlfn.DISPIMG("ID_E33C4A193FD84952A980861C4B8DD1E7",1) -> =DISPIMG("ID_E33C4A193FD84952A980861C4B8DD1E7",1) | F15: Changes has been done.
B16: R22, R25,R47,R96 | C16: 45761 | D16: IR receiver op-amp feedback resistor R22, R25,R47,R96 should always be 5K or below. | E16: =_xlfn.DISPIMG("ID_E64239F61E8C4EE4B55CFBEC8FD1F842",1) -> =DISPIMG("ID_E64239F61E8C4EE4B55CFBEC8FD1F842",1) | F16: Have to set manually.
B17: R7 | C17: 45761 | D17: Pipette R7 routing is missing for 3.3V. | E17: =_xlfn.DISPIMG("ID_813D6950A26B407C8D59F770CAB74333",1) -> =DISPIMG("ID_813D6950A26B407C8D59F770CAB74333",1) | F17: Changes has been done.
C18: 45761 | D18: Connect 12VB to the 12V pin. | E18: =_xlfn.DISPIMG("ID_EEBB852DB0E64F47A31FCCD3BA83C509",1) -> =DISPIMG("ID_EEBB852DB0E64F47A31FCCD3BA83C509",1) | F18: Changes has been done. Because we have 15V pin from power card.
B19: J18 | C19: 45761 | D19: Align J18 connector properly. | F19: Changes has been done.
B20: L4 | C20: 45761 | D20: Need to add ferrite bead between DGND and AGND. | E20: =_xlfn.DISPIMG("ID_E909EA5A4FDD4499A186A4081481F23D",1) -> =DISPIMG("ID_E909EA5A4FDD4499A186A4081481F23D",1) | F20: Changes has been done.
B21: R85,R67 | C21: 45761 | D21: Keep R85 and R67 as zero ohm | E21: =_xlfn.DISPIMG("ID_6C71ADB2F4B54669AAB6CDA90E22D5E8",1) -> =DISPIMG("ID_6C71ADB2F4B54669AAB6CDA90E22D5E8",1) | F21: Have to set manually.
B22: R21,R23 | C22: 45761 | D22: Set R21 and R23 to 20K. | E22: =_xlfn.DISPIMG("ID_015AA6EA26C844EA921F8A9D1FD76811",1) -> =DISPIMG("ID_015AA6EA26C844EA921F8A9D1FD76811",1) | F22: Changes has been done.
B23: J15 | C23: 45761 | D23: Verify J15 footprint. | F23: Changes has been done. L4 changed to R112 which is 0 ohm.
B24: L4 | C24: 45761 | D24: Keep L4 as zero ohm | E24: =_xlfn.DISPIMG("ID_C9136C83582F4A11B97FF33822DD4A7B",1) -> =DISPIMG("ID_C9136C83582F4A11B97FF33822DD4A7B",1) | F24: Changes has been done.
B25: J14 | C25: 45761 | D25: J14 connector +5V supply trace width need to increase | E25: =_xlfn.DISPIMG("ID_432AC574255D480B9AFDCD0517F381C3",1) -> =DISPIMG("ID_432AC574255D480B9AFDCD0517F381C3",1) | F25: Changes has been done. Updated on controller page.
B26: U6 | C26: 45761 | D26: Change U6 package to small SOIC, MFR PN: MAX3232CDR. | E26: =_xlfn.DISPIMG("ID_D4699378D1894BA9A734C03AB5522D91",1) -> =DISPIMG("ID_D4699378D1894BA9A734C03AB5522D91",1) | F26: Changes has been done.
B27: R108 | C27: 45761 | D27: Keep the value of R108 as 100K ohm. | E27: =_xlfn.DISPIMG("ID_1A47546BB4584A4FB482A4D2E593072E",1) -> =DISPIMG("ID_1A47546BB4584A4FB482A4D2E593072E",1) | F27: Changes has been done.
B28: J10 | C28: 45761 | D28: Add power supply marking for J10 connector on the silkscreen. | E28: =_xlfn.DISPIMG("ID_D37F93B8A6BF4D94995AF4186CADFBFB",1) -> =DISPIMG("ID_D37F93B8A6BF4D94995AF4186CADFBFB",1) | F28: Changes has been done in silkscreen.
B29: J19 | C29: 45890 | D29: Changed the power supply connectors (replacing 2 connectors from earlier versions into single connector) | E29: =_xlfn.DISPIMG("ID_C40B8C82DDF44D3B9927FAD266FAF7CB",1) -> =DISPIMG("ID_C40B8C82DDF44D3B9927FAD266FAF7CB",1) | F29: Changes has been done.
B30: J11 | C30: 45890 | D30: Added a separate connector near J6 (Pipette connector) for extra peripherals to add in future. | E30: =_xlfn.DISPIMG("ID_8B80AEFA9BF14FCD9EB3C50696B6BC72",1) -> =DISPIMG("ID_8B80AEFA9BF14FCD9EB3C50696B6BC72",1) | F30: Changes has been done.
B31: J9 | C31: 45890 | D31: Changed connector for new RFID module. | E31: =_xlfn.DISPIMG("ID_F1A25E0C8C6E4EE7A621054FAADB48B8",1) -> =DISPIMG("ID_F1A25E0C8C6E4EE7A621054FAADB48B8",1) | F31: Changes has been done.
C33: SOM Change
B34: SB127,SB125,SB133,SB132 | D34: Remove SB127,SB125,SB133,SB132 | E34: =_xlfn.DISPIMG("ID_15B0F0D79556480C80A48C8E5C526F3C",1) -> =DISPIMG("ID_15B0F0D79556480C80A48C8E5C526F3C",1)
B35: SB13,SB160,SB164,SB178,SB181,SB182,SB183 | D35: Remove SB13,SB160,SB164,SB178,SB181,SB182,SB183 | E35: =_xlfn.DISPIMG("ID_36814CA93F8A4A6EB7B8966FDEEAB2C2",1) -> =DISPIMG("ID_36814CA93F8A4A6EB7B8966FDEEAB2C2",1)
B36: JP6, JP7 | D36: Remove JP6, JP7 | E36: =_xlfn.DISPIMG("ID_CCDD50D8DFA7414B8FC61639EEC8334D",1) -> =DISPIMG("ID_CCDD50D8DFA7414B8FC61639EEC8334D",1)
B37: JP3 Vin_5 | D37: JP3 Vin_5 jumper always keep connected
B38: X3 | D38: X3 need to solder MFR PN- NX3225GD-8.000M-EXS00A-CG04874 | E38: =_xlfn.DISPIMG("ID_F80A23843E8A457D88D02E5FDAAE5112",1) -> =DISPIMG("ID_F80A23843E8A457D88D02E5FDAAE5112",1)
B39: C37,C38 | D39: Solder C37,C38 10pf/4.3 PF
B40: SB8,SB9 | D40: Solder SB8,SB9 zero Ohm res
D41: Disconnect the Nucleo programmer.
A44: <<INDEX

Sheet Visual Inspection
A1: <<INDEX
B2: Visual Inspection
B4: Test Group | C4: CQ2BB1
B5: Test Ref No. | C5: CQ2BB1
B6: Test Engineer | C6: Harshit Shakya
B7: Test Date | C7: 45894
B8: Hardware Details | C8: MD_MB_CLQTnew_V3
B9: Firmware Version | C9: NA
B10: Software version | C10: NA
B11: Test Name | C11: Visual Inspection
B12: Test Case Objective | C12: Visual verification of PCB to check for Silkscreen.
B13: Test Case Procedure | C13: Verification of Silkscreen | H13: Remark
C14: - All reference designators should be clearly visible. | G14: PASS
C15: - Marking for pin 1 near all IC footprints, connectors and other parts should be visible. | G15: PASS
C16: - All component outlines should be properly aligned and visible after the component is mounted | G16: PASS
C17: - All silkscreen labels should be visible and verify with the silkscreen verification sheet. | G17: PASS
C18: - Polarity marking should be available for the polarized components (Capacitor ,Diode, LED, Connectors) | G18: PASS
C19: - Using Fluke multimeter, measure and note down the resistance between the Supply rails and Ground rails as specified in the Bare Board Impedance Measurement Matrix. | G19: PASS
B21: Bare Board Impedance Measurement Matrix (Expected Result)*
B22: Test Signals | C22: -12V | D22: +12V | E22: +5V | F22: +3.3V | G22: DGND | H22: Test Result | I22: Remark
B23: -12V | C23: NA | G23: NA | H23: NA
B24: +12V | C24: OPEN | D24: NA | G24: NA | H24: NA
B25: +5V | C25: OPEN | D25: OPEN | E25: NA | G25: NA | H25: NA
B26: +3.3V | C26: OPEN | D26: OPEN | E26: OPEN | F26: NA | G26: NA | H26: NA
B27: DGND | C27: OPEN | D27: OPEN | E27: OPEN | F27: OPEN | G27: NA | H27: NA
B29: Bare Board Impedance Measurement Matrix (Expected Result)*
B30: Test Signals | C30: -12V | D30: +12V | E30: +5V | F30: +3.3V | G30: DGND | H30: Test Result | I30: Remark
B31: -12V | C31: NA | G31: NA | H31: NA
B32: +12V | C32: OPEN | D32: NA | G32: NA | H32: NA
B33: +5V | C33: OPEN | D33: OPEN | E33: NA | G33: NA | H33: NA
B34: +3.3V | C34: OPEN | D34: OPEN | E34: OPEN | F34: NA | G34: NA | H34: NA
B35: DGND | C35: OPEN | D35: OPEN | E35: OPEN | F35: OPEN | G35: NA | H35: NA
B37: Test Case Procedure | C37: Verification of Assembled Components | H37: Remark
C38: - All components should be assembled as per the assembly guidelines/BOM. | G38: PASS
C39: - All polarized components should be assembled correctly with proper polarity. | G39: PASS
C40: - All ICs should be oriented as per pin 1 marking in silkscreen. | G40: PASS
C41: - All components should be properly placed on their footprints. | G41: PASS
C42: - There should not be any soldering shorts or solder bridges on PCB | G42: PASS
C43: - There should not be any dry solder points | G43: PASS
B49: Test Result | C49: PASS
...

Sheet Impedance Measurement
A1: <<INDEX
B2: Assembled Board Impedance Measurement
B4: Test Group | C4: CQ2BB2
B5: Test Ref No. | C5: CQ2BB2
B6: Test Engineer | C6: Harshit Shakya
B7: Test Date | C7: 45894
B8: Hardware Details | C8: MD_MB_CLQTnew_V3
B9: Firmware Version | C9: NA
B10: Software version | C10: NA
B11: Test Name | C11: Pre power impedance measurements
B12: Test Case Objective | C12: Verify short / impedance between Supply rails and Ground rails
B13: Test Case Description | C13: 1. Using Fluke multimeter, measure and note down the resistance between the Supply rails and Ground rails as specified in the Assembled Board Impedance Measurement Matrix. 2. Update the test result
B15: Assembled Board Impedance Measurement Matrix (Expected Result)*
B16: Test Signals | C16: -12V | D16: +12V | E16: +5V | F16: +3.3V | G16: DGND | H16: Test Result | I16: Remark
B17: -12V | C17: - | D17: - | E17: - | F17: - | G17: - | H17: NA
B18: +12V | C18: - | D18: - | E18: - | F18: -
B19: +5V | C19: - | D19: - | E19: - | F19: - | G19: - | H19: NA
B20: +3.3V | C20: - | D20: - | E20: - | F20: - | G20: - | H20: NA
B21: DGND | C21: 0M | D21: 38.7M | E21: 11.2M | F21: 3.74K | G21: - | H21: NA
B23: Assembled Board Impedance Measurement Matrix
B24: Test Signals | C24: -12V | D24: +12V | E24: +5V | F24: +3.3V | G24: DGND | H24: Test Result | I24: Remark
B25: -12V | C25: - | D25: - | E25: - | F25: - | G25: - | H25: UNATTEMPTED
B26: +12V | C26: - | D26: - | E26: - | F26: - | G26: - | H26: UNATTEMPTED
B27: +5V | C27: - | D27: - | E27: - | F27: - | G27: - | H27: UNATTEMPTED
B28: +3.3V | C28: - | D28: - | E28: - | F28: - | G28: - | H28: UNATTEMPTED
B29: DGND | C29: 0M | D29: 38.7M | E29: 11.2M | F29: 3.74K | G29: - | H29: PASS
B31: Test Result | C31: PASS
A32: <<INDEX
F36: PASS
F37: FAIL
F38: UNATTEMPTED

Sheet Supply Rails
A1: <<INDEX
F2: Supply Rails Measurement
B4: Test Group | C4: CQ2BB3
B5: Test Ref No. | C5: CQ2BB3
B6: Test Engineer | C6: Harshit Shakya
B7: Test Date | C7: 45894
B8: Hardware Details | C8: MD_MB_CLQTnew_V3
B9: Firmware Version | C9: NA
B10: Software version | C10: NA
B11: Test Name | C11: Supply Rail and Ripple Measurements
B12: Test Case objective | C12: To verify tolerance and ripple of supply rail to be within +- 5 %
B13: Test Case Procedure | C13: Process - - Connect the Board to Back Panel and Power Card. - Turn on +12V to Power Card. - Measure and capture voltage +1.1V w.r.t. DGND - Measure and capture Ripple for + 1.8V w.r.t. DGND - Measure and capture voltage +1.2V w.r.t. DGND - Measure and capture Ripple for +3.3V w.r.t. DGND - Measure and capture voltage +5V w.r.t. DGND - Measure and capture Ripple for +0.85 w.r.t. DGND
B15: +12V Rail Voltage | H15: +12V Ripple Voltage
B16: Low Voltage Differential Probe Settings | C16: Coupling | E16: DC | H16: Low Voltage Differential Probe Settings | I16: Coupling | J16: AC
C17: Gain | E17: 1 | I17: Gain | J17: 1
C18: Bandwidth | E18: FULL | I18: Bandwidth | J18: FULL
B19: Scope Settings | C19: Coupling | E19: DC | H19: Scope Settings | I19: Coupling | J19: AC
C20: Bandwidth | E20: FULL | I20: Bandwidth | J20: FULL
C21: Trigger | E21: Rising Edge | I21: Trigger | J21: Rising Edge
B22: =_xlfn.DISPIMG("ID_6D4CE2CFC5F64A73AA8FCEC16C059EE1",1) -> =DISPIMG("ID_6D4CE2CFC5F64A73AA8FCEC16C059EE1",1) | H22: =_xlfn.DISPIMG("ID_8EA428021F70405EA6AFA0A79F405620",1) -> =DISPIMG("ID_8EA428021F70405EA6AFA0A79F405620",1)
B39: Expected Voltage | E39: Observed Voltage | H39: Expected Voltage | J39: Observed Ripple Voltage
B40: Test Result | C40: PASS | H40: Test Result | I40: PASS
B42: +5V Rail Voltage | H42: +5V Ripple Voltage
B43: Low Voltage Differential Probe Settings | C43: Coupling | E43: DC | H43: Low Voltage Differential Probe Settings | I43: Coupling | J43: AC
C44: Gain | E44: 1 | I44: Gain | J44: 1
C45: Bandwidth | E45: FULL | I45: Bandwidth | J45: FULL
B46: Scope Settings | C46: Coupling | E46: DC | H46: Scope Settings | I46: Coupling | J46: AC
C47: Bandwidth | E47: FULL | I47: Bandwidth | J47: FULL
C48: Trigger | E48: Rising Edge | I48: Trigger | J48: Rising Edge
B49: =_xlfn.DISPIMG("ID_53C63F431F8E450DB66412877B6165A9",1) -> =DISPIMG("ID_53C63F431F8E450DB66412877B6165A9",1) | H49: =_xlfn.DISPIMG("ID_93C28E6BF5D84AEFBFC213CC1F56CA51",1) -> =DISPIMG("ID_93C28E6BF5D84AEFBFC213CC1F56CA51",1)
B65: Expected Voltage | E65: Observed Voltage | H65: Expected Voltage | J65: Observed Ripple Voltage
B66: Test Result | C66: PASS | H66: Test Result | I66: PASS
B68: +3.3V Rail Voltage | H68: +3.3V Ripple Voltage
B69: Low Voltage Differential Probe Settings | C69: Coupling | E69: DC | H69: Low Voltage Differential Probe Settings | I69: Coupling | J69: AC
C70: Gain | E70: 1 | I70: Gain | J70: 1
C71: Bandwidth | E71: FULL | I71: Bandwidth | J71: FULL
B72: Scope Settings | C72: Coupling | E72: DC | H72: Scope Settings | I72: Coupling | J72: AC
C73: Bandwidth | E73: FULL | I73: Bandwidth | J73: FULL
C74: Trigger | E74: Rising Edge | I74: Trigger | J74: Rising Edge
B75: =_xlfn.DISPIMG("ID_3B1F1F37F3C2468EB1E908D47387CA9A",1) -> =DISPIMG("ID_3B1F1F37F3C2468EB1E908D47387CA9A",1) | H75: =_xlfn.DISPIMG("ID_340BA1B69D1F4387AE643EDF2343B5E0",1) -> =DISPIMG("ID_340BA1B69D1F4387AE643EDF2343B5E0",1)
...

Sheet Sheet1

Sheet SWD LED CODE FLASH
A1: <<INDEX
B2: SWD LED CODE FLASH
B4: Test Group | C4: CQ2BB4
B5: Test Ref No. | C5: CQ2BB4
B6: Test Engineer | C6: Harshit Shakya
B7: Test Date | C7: 45894
B8: Hardware Details | C8: MD_MB_CLQTnew_V3
B9: Firmware Version | C9: V1.0
B10: Software version | C10: STM32CubeIDE Version: 1.19.0
B11: Test Name | C11: Serial Wire Debugger LED code flash test
B12: Test Case Objective | C12: To verify functionality of Serial Wire Debugger
B13: Test Case Procedure | C13: Process - - Use connector J15 for SWD Debugger. - Power On the Board. - Connect SWD debugger (SWDIO, SWCLK, GND, NRST). - Verify MCU detection in the debugger tool or STM32CubeIDE. - Write simple LED blink code. - Reset the MCU after flashing. - Observe LED blinking.
D15: Expected Result | E15: Observed Result | F15: Test Result
E16: =_xlfn.DISPIMG("ID_86505F2351A246D3BAF4F5D8FD255048",1) -> =DISPIMG("ID_86505F2351A246D3BAF4F5D8FD255048",1) | F16: PASS
D18: Test Result | E18: PASS
A20: <<INDEX

Sheet Temprature Sensor
A1: <<INDEX
B2: Temperature Sensor
B4: Test Group | C4: CQ2BB5
B5: Test Ref No. | C5: CQ2BB5
B6: Test Engineer | C6: Harshit Shakya
B7: Test Date | C7: 45894
B8: Hardware Details | C8: MD_MB_CLQTnew_V3
B9: Firmware Version | C9: V1.0
B10: Software version | C10: STM32CubeIDE Version: 1.19.0
B11: Test Name | C11: Temperature Sensor Test
B12: Test Case Objective | C12: To verify functionality of Temperature Sensor
B13: Test Case Procedure | C13: Process - - Use connector J13 for Temperature Sensor (CT from J13). - Power On the System Manager Board. - Configure the ADC for 12-bit resolution in the firmware. -Flash the firmware to the Nucleo board. -Reset the board after flashing. -Read ADC values and convert them to temperature. -Verify sensor output with expected temperature range.
D15: Expected Result | E15: Observed Result | F15: Test Result
E16: =_xlfn.DISPIMG("ID_A73FADEF73994847BA0988067C9FF090",1) -> =DISPIMG("ID_A73FADEF73994847BA0988067C9FF090",1) | F16: PASS
D18: Test Result | E18: PASS
A20: <<INDEX

Sheet Display Test
A1: <<INDEX
B2: Display Test
B4: Test Group | C4: CQ2BB6
B5: Test Ref No. | C5: CQ2BB6
B6: Test Engineer | C6: Harshit Shakya
B7: Test Date | C7: 45894
B8: Hardware Details | C8: MD_MB_CLQTnew_V3
B9: Firmware Version | C9: V1.0
B10: Software version | C10: STM32CubeIDE Version: 1.19.0
B11: Test Name | C11: Display Test
B12: Test Case Objective | C12: To verify functionality of Display
B13: Test Case Procedure | C13: Process - - Use connector J14 for Display. - Power On the System Manager Board. - Connect the 7-inch UART display to the MCU (TX, RX, GND, VCC). -Initialize UART communication in the firmware. -Verify the received data from display. -Receive the data from display and perform LED operation. -Flash the firmware to the Nucleo board. -Reset the board after flashing. -Test touch inputs and verify correct data reception.
D15: Expected Result | E15: Observed Result | F15: Test Result
E16: =_xlfn.DISPIMG("ID_EA26FC03F4E64C6F85204D371C27E2A8",1) -> =DISPIMG("ID_EA26FC03F4E64C6F85204D371C27E2A8",1) | F16: PASS
E17: =_xlfn.DISPIMG("ID_623C35EBAB42466297410B738AE4BB87",1) -> =DISPIMG("ID_623C35EBAB42466297410B738AE4BB87",1)
D19: Test Result | E19: PASS
A21: <<INDEX

Sheet Pipette
A1: <<INDEX
B2: Pipette Test
B4: Test Group | C4: CQ2BB7
B5: Test Ref No. | C5: CQ2BB7
B6: Test Engineer | C6: Harshit Shakya
B7: Test Date | C7: 45894
B8: Hardware Details | C8: MD_MB_CLQTnew_V3
B9: Firmware Version | C9: V1.0
B10: Software version | C10: STM32CubeIDE Version: 1.19.0
B11: Test Name | C11: Pipette Test
B12: Test Case Objective | C12: To verify functionality of Pipette
B13: Test Case Procedure | C13: Process - - Use connector J6 for Pipette. - Power On the System Manager Board. - Connect the Pipette to Board - Press pipette Buton - Monitor the PC10 pin, if PC10 Pin High Send the puls on nucleo CS4 pin.
D15: Expected Result | E15: Observed Result | F15: Test Result
E16: Pipette is working properly. | F16: PASS
D18: Test Result | E18: PASS
A20: <<INDEX

Sheet Wifi module 
A1: <<INDEX
B2: Wifi Module Test
B4: Test Group | C4: CQ2BB8
B5: Test Ref No. | C5: CQ2BB8
B6: Test Engineer | C6: Harshit Shakya
B7: Test Date | C7: 45894
B8: Hardware Details | C8: MD_MB_CLQTnew_V3
B9: Firmware Version | C9: V1.0
B10: Software version | C10: STM32CubeIDE Version: 1.19.0
B11: Test Name | C11: Wifi Module Test
B12: Test Case Objective | C12: To verify functionality of Wifi Module
B13: Test Case Procedure | C13: Process - - Power On the System Manager Board. - Initialize communication in the firmware and driver files. - Configure the Wi-Fi module to connect to a network (SSID, password). - Flash the firmware to the Nucleo board. - Reset the board after flashing. - Verify connection by pinging a server or checking an IP address.
D15: Expected Result | E15: Observed Result | F15: Test Result
E16: =_xlfn.DISPIMG("ID_4B1A2B51068045A99380799A600DE1D0",1) -> =DISPIMG("ID_4B1A2B51068045A99380799A600DE1D0",1) | F16: PASS
D19: Test Result | E19: PASS
A21: <<INDEX

Sheet BLE
A1: <<INDEX
B2: BLE Test
B4: Test Group | C4: CQ2BB9
B5: Test Ref No. | C5: CQ2BB9
B6: Test Engineer | C6: Harshit Shakya
B7: Test Date | C7: 45894
B8: Hardware Details | C8: MD_MB_CLQTnew_V3
B9: Firmware Version | C9: V1.0
B10: Software version | C10: STM32CubeIDE Version: 1.19.0
B11: Test Name | C11: BLE Test
B12: Test Case Objective | C12: To verify functionality of BLE
B13: Test Case Procedure | C13: Process - - Power On the System Manager Board. - Initialize communication in the firmware. - Configure the BLE module in driver files. - Flash the firmware to the Nucleo board. - Reset the board after flashing. - Scan and connect using a BLE-enabled device (mobile app or another module). - Verify the connection of BLE and BLE address.
D15: Expected Result | E15: Observed Result | F15: Test Result
E16: =_xlfn.DISPIMG("ID_8F1594E4AAD24941899BB833EC9D8FB8",1) -> =DISPIMG("ID_8F1594E4AAD24941899BB833EC9D8FB8",1) | F16: PASS
E17: =_xlfn.DISPIMG("ID_A5086C6C0E8B4D93850002E4F166A2C1",1) -> =DISPIMG("ID_A5086C6C0E8B4D93850002E4F166A2C1",1)
D19: Test Result | E19: PASS
A21: <<INDEX

Sheet USB OTG1 Test
A1: <<INDEX
B2: USB Test
B4: Test Group | C4: CQ2BB10
B5: Test Ref No. | C5: CQ2BB10
B6: Test Engineer | C6: Harshit Shakya
B7: Test Date | C7: 45894
B8: Hardware Details | C8: MD_MB_CLQTnew_V3
B9: Firmware Version | C9: V1.0
B10: Software version | C10: STM32CubeIDE Version: 1.19.0
B11: Test Name | C11: USB OTG1 Test
B12: Test Case Objective | C12: To verify functionality of USB
B13: Test Case Procedure | C13: Process - - Use connector J1 for USB OTG1. - Power On the System Manager Board. - Connect the USB OTG adapter and pen drive to the board. - Initialize USB Host mode in the firmware. - Detect the USB device connection. - Mount the file system on the pen drive. - Read and write a test file to verify functionality. - Flash the firmware to the Nucleo board. - Reset the board after flashing. - Verify data integrity by checking the file contents.
C15: Expected Result | D15: Observed Result | E15: Test Result
D16: =_xlfn.DISPIMG("ID_61661EA0A74946AD8B2473FC4A162C06",1) -> =DISPIMG("ID_61661EA0A74946AD8B2473FC4A162C06",1) | E16: PASS
C19: Test Result | D19: PASS
B20: <<INDEX

Sheet USB OTG2 Test
A1: <<INDEX
B2: USB Test
B4: Test Group | C4: CQ2BB11
B5: Test Ref No. | C5: CQ2BB11
B6: Test Engineer | C6: Harshit Shakya
B7: Test Date | C7: 45894
B8: Hardware Details | C8: MD_MB_CLQTnew_V3
B9: Firmware Version | C9: V1.0
B10: Software version | C10: STM32CubeIDE Version: 1.19.0
B11: Test Name | C11: USB OTG2 Test
B12: Test Case Objective | C12: To verify functionality of USB
B13: Test Case Procedure | C13: Process - - Use connector J2 for USB OTG2. - Power On the System Manager Board. - Connect the USB OTG adapter and pen drive to the board. - Initialize USB Host mode in the firmware. - Detect the USB device connection. - Mount the file system on the pen drive. - Read and write a test file to verify functionality. - Flash the firmware to the Nucleo board. - Reset the board after flashing. - Verify data integrity by checking the file contents.
C15: Expected Result | D15: Observed Result | E15: Test Result
D16: =_xlfn.DISPIMG("ID_5B17E7B64BDC4840B1A17D36AF91CDCA",1) -> =DISPIMG("ID_5B17E7B64BDC4840B1A17D36AF91CDCA",1) | E16: PASS
C19: Test Result | D19: PASS
B20: <<INDEX

Sheet RFID
A1: <<INDEX
B2: RFID Test
B4: Test Group | C4: CQ2BB12
B5: Test Ref No. | C5: CQ2BB12
B6: Test Engineer | C6: Harshit Shakya
B7: Test Date | C7: 45894
B8: Hardware Details | C8: MD_MB_CLQTnew_V3
B9: Firmware Version | C9: V1.0
B10: Software version | C10: STM32CubeIDE Version: 1.19.0
B11: Test Name | C11: RFID Test
B12: Test Case Objective | C12: To verify functionality of RFID
B13: Test Case Procedure | C13: Process - - Use connector J9 for RFID. - Power On the System Manager Board. - Connect the RFID module to the MCU - Initialize communication in the firmware. - Send a test command to check module response. - Flash the firmware to the Nucleo board. - Reset the board after flashing. - Scan an RFID tag and read its unique ID. - Verify the received data with expected values.
D15: Expected Result | E15: Observed Result | F15: Test Result
E16: =_xlfn.DISPIMG("ID_5888C88F69C8473CBD2D75CEB064CFD2",1) -> =DISPIMG("ID_5888C88F69C8473CBD2D75CEB064CFD2",1) | F16: PASS
D19: Test Result | E19: PASS
A21: <<INDEX

Sheet Printer
A1: <<INDEX
B2: Printer Test
B4: Test Group | C4: CQ2BB13
B5: Test Ref No. | C5: CQ2BB13
B6: Test Engineer | C6: Harshit Shakya
B7: Test Date | C7: 45894
B8: Hardware Details | C8: MD_MB_CLQTnew_V3
B9: Firmware Version | C9: v1.0
B10: Software version | C10: STM32CubeIDE Version: 1.19.0
B11: Test Name | C11: Printer Test
B12: Test Case Objective | C12: To verify functionality of Printer
B13: Test Case Procedure | C13: Process - - Use connector J7 for Printer Power and J12 for Pinter Connection. - Power On the System Manager Board. -Initialize communication in the firmware. -Send a test print command (e.g., "Hello, World!"). -Flash the firmware to the Nucleo board. - Reset the board after flashing. - Verify that the printer prints the test message correctly.
D15: Expected Result | E15: Observed Result | F15: Test Result
E16: =_xlfn.DISPIMG("ID_DE2ABA55A5404AD6BC72E7FE205E5E6E",1) -> =DISPIMG("ID_DE2ABA55A5404AD6BC72E7FE205E5E6E",1) | F16: PASS
D18: Test Result | E18: PASS
A20: <<INDEX

Sheet Ethernet
A1: <<INDEX
B2: Ethernet Test
B4: Test Group | C4: CQ2BB14
B5: Test Ref No. | C5: CQ2BB14
B6: Test Engineer | C6: Harshit Shakya
B7: Test Date | C7: 45894
B8: Hardware Details | C8: MD_MB_CLQTnew_V3
B9: Firmware Version | C9: V1.0
B10: Software version | C10: STM32CubeIDE Version: 1.19.0
B11: Test Name | C11: Ethernet Test
B12: Test Case Objective | C12: To verify functionality of Ethernet
B13: Test Case Procedure | C13: Process - - Use connector J18 for Ethernet Testing. - Power On the System Manager Board. - Connect the board to a network via an Ethernet cable. - Initialize the Ethernet interface in the firmware. - Flash the firmware to the Nucleo board. - Reset the board after flashing. - Obtain an IP address via DHCP or set a static IP. - Ping the board from a PC to verify connectivity. - Test data transmission by sending and receiving packets.
C15: Expected Result | D15: Observed Result | E15: Test Result
C16: Ping from both sides should result in verifying correct link establishment | D16: =_xlfn.DISPIMG("ID_B055495C3FDC43AD916990FEA161AC12",1) -> =DISPIMG("ID_B055495C3FDC43AD916990FEA161AC12",1) | E16: PASS
D17: =_xlfn.DISPIMG("ID_6E23CEE7991247E88E3ACEC285030820",1) -> =DISPIMG("ID_6E23CEE7991247E88E3ACEC285030820",1)
D18: =_xlfn.DISPIMG("ID_3158C83935BC49309808493199235372",1) -> =DISPIMG("ID_3158C83935BC49309808493199235372",1)
C20: Test Result | D20: PASS
A23: <<INDEX

Sheet Heater 
A1: <<INDEX
B2: Heater Test
B4: Test Group | C4: CQ2BB15
B5: Test Ref No. | C5: CQ2BB15
B6: Test Engineer | C6: Harshit Shakya
B7: Test Date | C7: 45894
B8: Hardware Details | C8: MD_MB_CLQTnew_V3
B9: Firmware Version | C9: V1.0
B10: Software version | C10: STM32CubeIDE Version: 1.19.0
B11: Test Name | C11: Heater Test
B12: Test Case Objective | C12: To verify functionality of Heater
B13: Test Case Procedure | C13: Process - - Use connector J5 for Heater. - Power On the System Manager Board. - Initialize GPIO output for heater control in the firmware. - Flash the firmware to the Nucleo board. - Reset the board after flashing. - Send a command or set a condition to turn the heater ON. - Verify heater activation (check voltage or temperature rise). - Send a command or set a condition to turn the heater OFF.
D15: Expected Result | E15: Observed Result | F15: Test Result
E16: =_xlfn.DISPIMG("ID_CE9C7081A13D489C8D551AC7DBD39CD9",1) -> =DISPIMG("ID_CE9C7081A13D489C8D551AC7DBD39CD9",1) | F16: PASS
D18: Test Result | E18: PASS
A20: <<INDEX

Sheet SDRAM
A1: <<INDEX
B2: SDRAM Memory Test
B4: Test Group | C4: CQ2BB16
B5: Test Ref No. | C5: CQ2BB16
B6: Test Engineer | C6: Harshit Shakya
B7: Test Date | C7: 45894
B8: Hardware Details | C8: MD_MB_CLQTnew_V3
B9: Firmware Version | C9: V1.0
B10: Software version | C10: STM32CubeIDE Version: 1.19.0
B11: Test Name | C11: SDRAM Memory Test
B12: Test Case Objective | C12: To verify functionality of SDRAM Memory
B13: Test Case Procedure | C13: Process - - Power On the System Manager Board. - Initialize SDRAM controller in the firmware. - Flash the firmware to the Nucleo board. - Reset the board after flashing. - Perform a write test (store known data in SDRAM). - Perform a read test (verify stored data matches expected values). - Verify data integrity and SDRAM stability.
D15: Expected Result | E15: Observed Result | F15: Test Result
E16: =_xlfn.DISPIMG("ID_5082A422A79F4C50B42816466746A477",1) -> =DISPIMG("ID_5082A422A79F4C50B42816466746A477",1) | F16: PASS
D18: Test Result | E18: PASS
A20: <<INDEX

Sheet QSPI Flash
A1: <<INDEX
B2: QSPI Flash Test
B4: Test Group | C4: CQ2BB17
B5: Test Ref No. | C5: CQ2BB17
B6: Test Engineer | C6: Harshit Shakya
B7: Test Date | C7: 45894
B8: Hardware Details | C8: MD_MB_CLQTnew_V3
B9: Firmware Version | C9: V1.0
B10: Software version | C10: STM32CubeIDE Version: 1.19.0
B11: Test Name | C11: QSPI Flash Test
B12: Test Case Objective | C12: To verify functionality of QSPI Flash
B13: Test Case Procedure | C13: Process - - Power On the System Manager Board. - Flash the firmware to the Nucleo board. - Reset the board after flashing. - Perform a write test (store known data in QSPI memory). - Perform a read test (verify stored data matches expected values). - Run an erase test and verify memory clearing. - Check data integrity and QSPI performance
D15: Expected Result | E15: Observed Result | F15: Test Result
E16: =_xlfn.DISPIMG("ID_BAD2BF8D9BDF4A168BBCDAB9CF077FD7",1) -> =DISPIMG("ID_BAD2BF8D9BDF4A168BBCDAB9CF077FD7",1) | F16: PASS
D18: Test Result | E18: PASS
A20: <<INDEX

Sheet ADC
A1: <<INDEX
B2: ADC Test
B4: Test Group | C4: CQ2BB18
B5: Test Ref No. | C5: CQ2BB18
B6: Test Engineer | C6: Harshit Shakya
B7: Test Date | C7: 45894
B8: Hardware Details | C8: MD_MB_CLQTnew_V3
B9: Firmware Version | C9: V1.0
B10: Software version | C10: STM32CubeIDE Version: 1.19.0
B11: Test Name | C11: ADC Test
B12: Test Case Objective | C12: To verify functionality of ADC
B13: Test Case Procedure | C13: Process - - Power On the System Manager Board. - Configure SPI settings in the firmware (clock speed, mode, data format). - Flash the firmware to the Nucleo board. - Reset the board after flashing. - Read ADC values from the connected channels. - Convert raw ADC data to voltage values. - Verify readings using a known voltage source or sensor input.
D15: Expected Result | E15: Observed Result | F15: Test Result
E16: =_xlfn.DISPIMG("ID_6CE15B985E1B40309D2EBD2FAAC7CF69",1) -> =DISPIMG("ID_6CE15B985E1B40309D2EBD2FAAC7CF69",1) | F16: PASS
D18: Test Result | E18: PASS
A20: <<INDEX

Sheet IR LED test 
A1: <<INDEX
B2: IR LED Test
B4: Test Group | C4: CQ2BB19
B5: Test Ref No. | C5: CQ2BB19
B6: Test Engineer | C6: Harshit Shakya
B7: Test Date | C7: 45894
B8: Hardware Details | C8: MD_MB_CLQTnew_V3
B9: Firmware Version | C9: NA
B10: Software version | C10: NA
B11: Test Name | C11: IR LED Test
B12: Test Case Objective | C12: To verify IR LED working properly
B13: Test Case Procedure | C13: Process - - Use connector J8 for IR LED Testing. - Power On the System Manager Board. - Expose the photo transistor to different light levels. - Read ADC values and convert them to voltage. - Verify response by observing voltage changes with varying light intensity.
D15: Expected Result | E15: Observed Result | F15: Test Result
E16: IR LED is working properly. | F16: PASS
D18: Test Result | E18: PASS
A20: <<INDEX

Sheet RS232
A1: <<INDEX
B2: RS232 Test
B4: Test Group | C4: CQ2BB20
B5: Test Ref No. | C5: CQ2BB20
B6: Test Engineer | C6: Harshit Shakya
B7: Test Date | C7: 45894
B8: Hardware Details | C8: MD_MB_CLQTnew_V3
B9: Firmware Version | C9: V1.0
B10: Software version | C10: STM32CubeIDE Version: 1.19.0
B11: Test Name | C11: RS232 Test
B12: Test Case Objective | C12: To verify functionality of RS232
B13: Test Case Procedure | C13: Process - - Use connector J3 for RS232 Testing. - Power On the System Manager Board. - Configure UART settings in the firmware (baud rate, parity, stop bits). - Flash the firmware to the Nucleo board. - Reset the board after flashing. - Send a test message from the MCU over RS232. - Receive the message on a PC or another device using a serial terminal. - Verify data integrity by checking if the sent and received messages match.
D15: Expected Result | E15: Observed Result | F15: Test Result
E16: =_xlfn.DISPIMG("ID_F23CB39EAE30448CBDFEEA7409904D80",1) -> =DISPIMG("ID_F23CB39EAE30448CBDFEEA7409904D80",1) | F16: PASS
D18: Test Result | E18: PASS
A20: <<INDEX

Sheet BUZZER
A1: <<INDEX
B2: BUZZER Test
B4: Test Group | C4: CQ2BB21
B5: Test Ref No. | C5: CQ2BB21
B6: Test Engineer | C6: Harshit Shakya
B7: Test Date | C7: 45894
B8: Hardware Details | C8: MD_MB_CLQTnew_V3
B9: Firmware Version | C9: V1.0
B10: Software version | C10: STM32CubeIDE Version: 1.19.0
B11: Test Name | C11: Buzzer Test
B12: Test Case Objective | C12: To verify functionality of Buzzer
B13: Test Case Procedure | C13: Process - - Power On the System Manager Board. - configure the GPIO as an output in the firmware. - Flash the firmware to the Nucleo board. - Reset the board after flashing. - Set the GPIO HIGH to turn the buzzer ON. - Set the GPIO LOW to turn the buzzer OFF. - Verify the buzzer sound activation and deactivation.
D15: Expected Result | E15: Observed Result | F15: Test Result
E16: Buzzer is working properly. | F16: PASS
D18: Test Result | E18: PASS
A20: <<INDEX

Sheet FAN
A1: <<INDEX
B2: FAN Test
B4: Test Group | C4: CQ2BB22
B5: Test Ref No. | C5: CQ2BB22
B6: Test Engineer | C6: Harshit Shakya
B7: Test Date | C7: 45894
B8: Hardware Details | C8: MD_MB_CLQTnew_V3
B9: Firmware Version | C9: NA
B10: Software version | C10: NA
B11: Test Name | C11: Fan Test
B12: Test Case Objective | C12: To verify Fan working properly
B13: Test Case Procedure | C13: Process - - Use connector J14 for Fan Testing. - Power ON the System Manager Board. - Connect the FAN.
D15: Expected Result | E15: Observed Result | F15: Test Result
E16: Fan is working properly. | F16: PASS
D18: Test Result | E18: PASS
A20: <<INDEX

Sheet RTC
A1: <<INDEX
B2: RTC Test
B4: Test Group | C4: CQ2BB23
B5: Test Ref No. | C5: CQ2BB23
B6: Test Engineer | C6: Harshit Shakya
B7: Test Date | C7: 45894
B8: Hardware Details | C8: MD_MB_CLQTnew_V3
B9: Firmware Version | C9: V1.0
B10: Software version | C10: STM32CubeIDE Version: 1.18.0
B11: Test Name | C11: RTC Test
B12: Test Case Objective | C12: To verify the functionality of RTC.
B13: Test Case Procedure | C13: Process - - Power On the System Manager Board. - Connect a backup battery (if required) to the RTC module. - Initialize the RTC peripheral in the firmware. - Flash the firmware to the Nucleo board. - Reset the board after flashing. - Set the current date and time in the RTC. - Read and display the RTC time. - Power cycle the board and verify if the RTC maintains the correct time.
D15: Expected Result | E15: Observed Result | F15: Test Result
E16: =_xlfn.DISPIMG("ID_10D7CEE562B5450DA7A232D26C7FA72F",1) -> =DISPIMG("ID_10D7CEE562B5450DA7A232D26C7FA72F",1) | F16: PASS
D18: Test Result | E18: PASS
A20: <<INDEX

Sheet Encryption IC
A1: <<INDEX
B2: Encryption IC
B4: Test Group | C4: CQ2BB24
B5: Test Ref No. | C5: CQ2BB24
B6: Test Engineer | C6: Harshit Shakya
B7: Test Date | C7: 45894
B8: Hardware Details | C8: MD_MB_CLQTnew_V3
B9: Firmware Version | C9: V1.0
B10: Software version | C10: STM32CubeIDE Version: 1.19.0
B11: Test Name | C11: Encryption IC Test
B12: Test Case Objective | C12: To verify the functionality of Encryption IC
B13: Test Case Procedure | C13: Process - - Power On the Board. - Initialize I²C peripheral on MCU (pins connected to ATSHA204A SDA & SCL). - Send I²C wake-up sequence to ATSHA204A. - Verify device acknowledgment on I²C bus. - Send “Read Serial Number” command to ATSHA204A. - Confirm valid serial number response is received. - Execute “Random Number” command to verify proper operation. - Check response data format and length (matches datasheet spec). - Reset the MCU after test execution. - Confirm ATSHA204A responds correctly after reset.
D15: Expected Result | E15: Observed Result | F15: Test Result
F16: UNATTEMPTED
D18: Test Result | E18: UNATTEMPTED
A20: <<INDEX

Sheet J11
A1: <<INDEX
B2: Connector J11 Test
B4: Test Group | C4: CQ2BB25
B5: Test Ref No. | C5: CQ2BB25
B6: Test Engineer | C6: Harshit Shakya
B7: Test Date | C7: 45894
B8: Hardware Details | C8: MD_MB_CLQTnew_V3
B9: Firmware Version | C9: V1.0
B10: Software version | C10: STM32CubeIDE Version: 1.19.0
B11: Test Name | C11: Connector J11 Test
B12: Test Case Objective | C12: To verify the connector J11 is connected with MCU properly
B13: Test Case Procedure | C13: Process - - Use connector J11 (3-pin GPIO connector). - Power On the Board. - Configure 3 GPIO pins in firmware as digital outputs. - Connect DMM to the 3 GPIO pins and GND. - Toggle each GPIO pin HIGH → LOW in sequence with delay. - Verify voltage transitions on all 3 pins using measurement tool. - Reset the MCU after test execution. - Confirm all GPIO pins return to default LOW state.
D15: Expected Result | E15: Observed Result | F15: Test Result
F16: UNATTEMPTED
D18: Test Result | E18: UNATTEMPTED
A20: <<INDEX
